Traceback (most recent call last):
  File "/usr/local/python/3.12.1/lib/python3.12/site-packages/jupyter_cache/executors/utils.py", line 58, in single_nb_execution
    executenb(
  File "/home/codespace/.local/lib/python3.12/site-packages/nbclient/client.py", line 1314, in execute
    return NotebookClient(nb=nb, resources=resources, km=km, **kwargs).execute()
           ^^^^^^^^^^^^^^^^^^^^^^^^^^^^^^^^^^^^^^^^^^^^^^^^^^^^^^^^^^^^^^^^^^^^^
  File "/home/codespace/.local/lib/python3.12/site-packages/jupyter_core/utils/__init__.py", line 165, in wrapped
    return loop.run_until_complete(inner)
           ^^^^^^^^^^^^^^^^^^^^^^^^^^^^^^
  File "/usr/local/python/3.12.1/lib/python3.12/asyncio/base_events.py", line 684, in run_until_complete
    return future.result()
           ^^^^^^^^^^^^^^^
  File "/home/codespace/.local/lib/python3.12/site-packages/nbclient/client.py", line 709, in async_execute
    await self.async_execute_cell(
  File "/home/codespace/.local/lib/python3.12/site-packages/nbclient/client.py", line 1062, in async_execute_cell
    await self._check_raise_for_error(cell, cell_index, exec_reply)
  File "/home/codespace/.local/lib/python3.12/site-packages/nbclient/client.py", line 918, in _check_raise_for_error
    raise CellExecutionError.from_cell_and_msg(cell, exec_reply_content)
nbclient.exceptions.CellExecutionError: An error occurred while executing the following cell:
------------------
from sklearn.impute import SimpleImputer
from sklearn.preprocessing import StandardScaler

# 1. Imputasi missing value dengan rata-rata
imputer = SimpleImputer(strategy='mean')
df_imputed = pd.DataFrame(imputer.fit_transform(df), columns=df.columns)

# 2. Normalisasi fitur numerik
numerical_cols = df_imputed.select_dtypes(include=['float64', 'int64']).columns.drop('target')
scaler = StandardScaler()
df_imputed[numerical_cols] = scaler.fit_transform(df_imputed[numerical_cols])

# 3. (Opsional) Binning usia
df_imputed['age_bin'] = pd.cut(df_imputed['age'], bins=[0, 40, 60, 100], labels=['muda', 'dewasa', 'lanjut'])

# Cek hasil akhir
print("\nHasil preprocessing:")
print(df_imputed.head())

------------------


[0;31m---------------------------------------------------------------------------[0m
[0;31mKeyError[0m                                  Traceback (most recent call last)
Cell [0;32mIn[6], line 9[0m
[1;32m      6[0m df_imputed [38;5;241m=[39m pd[38;5;241m.[39mDataFrame(imputer[38;5;241m.[39mfit_transform(df), columns[38;5;241m=[39mdf[38;5;241m.[39mcolumns)
[1;32m      8[0m [38;5;66;03m# 2. Normalisasi fitur numerik[39;00m
[0;32m----> 9[0m numerical_cols [38;5;241m=[39m [43mdf_imputed[49m[38;5;241;43m.[39;49m[43mselect_dtypes[49m[43m([49m[43minclude[49m[38;5;241;43m=[39;49m[43m[[49m[38;5;124;43m'[39;49m[38;5;124;43mfloat64[39;49m[38;5;124;43m'[39;49m[43m,[49m[43m [49m[38;5;124;43m'[39;49m[38;5;124;43mint64[39;49m[38;5;124;43m'[39;49m[43m][49m[43m)[49m[38;5;241;43m.[39;49m[43mcolumns[49m[38;5;241;43m.[39;49m[43mdrop[49m[43m([49m[38;5;124;43m'[39;49m[38;5;124;43mtarget[39;49m[38;5;124;43m'[39;49m[43m)[49m
[1;32m     10[0m scaler [38;5;241m=[39m StandardScaler()
[1;32m     11[0m df_imputed[numerical_cols] [38;5;241m=[39m scaler[38;5;241m.[39mfit_transform(df_imputed[numerical_cols])

File [0;32m~/.local/lib/python3.12/site-packages/pandas/core/indexes/base.py:7070[0m, in [0;36mIndex.drop[0;34m(self, labels, errors)[0m
[1;32m   7068[0m [38;5;28;01mif[39;00m mask[38;5;241m.[39many():
[1;32m   7069[0m     [38;5;28;01mif[39;00m errors [38;5;241m!=[39m [38;5;124m"[39m[38;5;124mignore[39m[38;5;124m"[39m:
[0;32m-> 7070[0m         [38;5;28;01mraise[39;00m [38;5;167;01mKeyError[39;00m([38;5;124mf[39m[38;5;124m"[39m[38;5;132;01m{[39;00mlabels[mask][38;5;241m.[39mtolist()[38;5;132;01m}[39;00m[38;5;124m not found in axis[39m[38;5;124m"[39m)
[1;32m   7071[0m     indexer [38;5;241m=[39m indexer[[38;5;241m~[39mmask]
[1;32m   7072[0m [38;5;28;01mreturn[39;00m [38;5;28mself[39m[38;5;241m.[39mdelete(indexer)

[0;31mKeyError[0m: "['target'] not found in axis"

